<mujoco model="Lite3">
  <compiler angle="radian" meshdir="../meshes/"/>

  <asset>
    <mesh name="torso" content_type="model/stl" file="torso.STL"/>
    <mesh name="hip" content_type="model/stl" file="hip.STL"/>
    <mesh name="thigh" content_type="model/stl" file="thigh.STL"/>
    <mesh name="shank" content_type="model/stl" file="shank.STL"/>
    <mesh name="hip1" content_type="model/stl" file="hip.STL" scale="1 -1 1"/>
    <mesh name="thigh1" content_type="model/stl" file="thigh.STL" scale="1 -1 1"/>
    <mesh name="hip2" content_type="model/stl" file="hip.STL" scale="-1 1 1"/>
    <mesh name="hip3" content_type="model/stl" file="hip.STL" scale="-1 -1 1"/>
  </asset>

  <worldbody>
    <body name="TORSO">
      <inertial pos="0 0 0" quat="0 0.707107 0 0.707107" mass="5.6056" diaginertia="0.07016 0.05518 0.02456"/>
      <geom type="mesh" contype="0" conaffinity="0" group="1" density="0" mesh="torso"/>
      <geom size="0.25 0.05 0.06" pos="0 0 0.01" type="box"/>
      <geom size="0.125 0.1 0.06" pos="0 0 0.01" type="box"/>
      <body name="FL_HIP" pos="0.1745 0.062 0">
        <inertial pos="-0.00601 -0.0066532 0.00034295" quat="0 0.707107 0 0.707107" mass="0.55" diaginertia="0.0004472 0.0004028 0.0003949"/>
        <joint name="FL_HipX_joint" pos="0 0 0" axis="-1 0 0" range="-0.523 0.523" actuatorfrcrange="-24 24"/>
        <geom type="mesh" contype="0" conaffinity="0" group="1" density="0" mesh="hip"/>
        <geom size="0.04 0.075" pos="0 0.05 0" quat="0.707107 0.707107 0 0" type="cylinder"/>
        <body name="FL_THIGH" pos="0 0.09735 0">
          <inertial pos="-0.0052817 -0.014632 -0.042672" mass="0.86" diaginertia="0.005736 0.00496 0.001436"/>
          <joint name="FL_HipY_joint" pos="0 0 0" axis="0 -1 0" range="-2.67 0.314" actuatorfrcrange="-24 24"/>
          <geom type="mesh" contype="0" conaffinity="0" group="1" density="0" mesh="thigh"/>
          <geom size="0.02 0.0225 0.1" pos="-0.015 0 -0.08" type="box"/>
          <body name="FL_SHANK" pos="0 0 -0.2">
            <inertial pos="0.0064794 -1.4535e-06 -0.12157" quat="0.707107 0 0 0.707107" mass="0.153" diaginertia="0.00090672 0.00089039 3.1266e-05"/>
            <joint name="FL_Knee_joint" pos="0 0 0" axis="0 -1 0" range="0.524 2.792" actuatorfrcrange="-36 36"/>
            <geom type="mesh" contype="0" conaffinity="0" group="1" density="0" rgba="1 1 1 1" mesh="shank"/>
            <geom size="0.015 0.06" pos="0.005 0 -0.03" quat="0.995004 0 -0.0998334 0" type="cylinder" rgba="1 1 1 1"/>
            <geom size="0.015 0.05" pos="0.01 0 -0.14" quat="0.997189 0 0.0749297 0" type="cylinder" rgba="1 1 1 1"/>
            <body name="FL_FOOT" pos="0 0 -0.21012">
              <inertial pos="0 0 0" mass="0.02" diaginertia="0 0 0"/>
              <geom size="0.022" quat="0.707107 0.707107 0 0"/>
            </body>
          </body>
        </body>
      </body>
      <body name="FR_HIP" pos="0.1745 -0.062 0">
        <inertial pos="-0.010579 0.011358 0.00048546" mass="0.55" diaginertia="0.0004472 0.0004028 0.0003949"/>
        <joint name="FR_HipX_joint" pos="0 0 0" axis="-1 0 0" range="-0.523 0.523" actuatorfrcrange="-24 24"/>
        <geom type="mesh" contype="0" conaffinity="0" group="1" density="0" mesh="hip1"/>
        <geom size="0.04 0.075" pos="0 -0.05 0" quat="0.707107 0.707107 0 0" type="cylinder"/>
        <body name="FR_THIGH" pos="0 -0.09735 0">
          <inertial pos="-0.0039245 0.025256 -0.025146" mass="0.86" diaginertia="0.005736 0.00496 0.001436"/>
          <joint name="FR_HipY_joint" pos="0 0 0" axis="0 -1 0" range="-2.67 0.314" actuatorfrcrange="-24 24"/>
          <geom type="mesh" contype="0" conaffinity="0" group="1" density="0" mesh="thigh1"/>
          <geom size="0.02 0.0225 0.1" pos="-0.015 0 -0.08" type="box"/>
          <body name="FR_SHANK" pos="0 0 -0.2">
            <inertial pos="0.0064794 -1.4552e-06 -0.12157" quat="0.707107 0 0 0.707107" mass="0.153" diaginertia="0.00090672 0.00089039 3.1266e-05"/>
            <joint name="FR_Knee_joint" pos="0 0 0" axis="0 -1 0" range="0.524 2.792" actuatorfrcrange="-36 36"/>
            <geom type="mesh" contype="0" conaffinity="0" group="1" density="0" mesh="shank"/>
            <geom size="0.015 0.06" pos="0.005 0 -0.03" quat="0.995004 0 -0.0998334 0" type="cylinder"/>
            <geom size="0.015 0.05" pos="0.01 0 -0.14" quat="0.997189 0 0.0749297 0" type="cylinder"/>
            <body name="FR_FOOT" pos="0 0 -0.21012">
              <inertial pos="0 0 0" mass="0.02" diaginertia="0 0 0"/>
              <geom size="0.022" quat="0.707107 0.707107 0 0"/>
            </body>
          </body>
        </body>
      </body>
      <body name="HL_HIP" pos="-0.1745 0.062 0">
        <inertial pos="0.010905 -0.012636 0.001051" quat="0 0.707107 0 0.707107" mass="0.55" diaginertia="0.0004472 0.0004028 0.0003949"/>
        <joint name="HL_HipX_joint" pos="0 0 0" axis="-1 0 0" range="-0.523 0.523" actuatorfrcrange="-24 24"/>
        <geom type="mesh" contype="0" conaffinity="0" group="1" density="0" mesh="hip2"/>
        <geom size="0.04 0.075" pos="0 0.05 0" quat="0.707107 0.707107 0 0" type="cylinder"/>
        <body name="HL_THIGH" pos="0 0.09735 0">
          <inertial pos="-0.0057137 -0.014631 -0.042453" mass="0.86" diaginertia="0.005736 0.00496 0.001436"/>
          <joint name="HL_HipY_joint" pos="0 0 0" axis="0 -1 0" range="-2.67 0.314" actuatorfrcrange="-24 24"/>
          <geom type="mesh" contype="0" conaffinity="0" group="1" density="0" mesh="thigh"/>
          <geom size="0.02 0.0225 0.1" pos="-0.015 0 -0.08" type="box"/>
          <body name="HL_SHANK" pos="0 0 -0.2">
            <inertial pos="0.0064794 -1.4558e-06 -0.12157" quat="0.707107 0 0 0.707107" mass="0.153" diaginertia="0.00090672 0.00089039 3.1266e-05"/>
            <joint name="HL_Knee_joint" pos="0 0 0" axis="0 -1 0" range="0.524 2.792" actuatorfrcrange="-36 36"/>
            <geom type="mesh" contype="0" conaffinity="0" group="1" density="0" mesh="shank"/>
            <geom size="0.015 0.06" pos="0.005 0 -0.03" quat="0.995004 0 -0.0998334 0" type="cylinder"/>
            <geom size="0.015 0.05" pos="0.01 0 -0.14" quat="0.997189 0 0.0749297 0" type="cylinder"/>
            <body name="HL_FOOT" pos="0 0 -0.21012">
              <inertial pos="0 0 0" mass="0.02" diaginertia="0 0 0"/>
              <geom size="0.022" quat="0.707107 0.707107 0 0"/>
            </body>
          </body>
        </body>
      </body>
      <body name="HR_HIP" pos="-0.1745 -0.062 0">
        <inertial pos="0.010354 0.011423 0.00049498" mass="0.55" diaginertia="0.0004472 0.0004028 0.0003949"/>
        <joint name="HR_HipX_joint" pos="0 0 0" axis="-1 0 0" range="-0.523 0.523" actuatorfrcrange="-24 24"/>
        <geom type="mesh" contype="0" conaffinity="0" group="1" density="0" mesh="hip3"/>
        <geom size="0.04 0.075" pos="0 -0.05 0" quat="0.707107 0.707107 0 0" type="cylinder"/>
        <body name="HR_THIGH" pos="0 -0.09735 0">
          <inertial pos="-0.0031903 0.02526 -0.025617" mass="0.86" diaginertia="0.005736 0.00496 0.001436"/>
          <joint name="HR_HipY_joint" pos="0 0 0" axis="0 -1 0" range="-2.67 0.314" actuatorfrcrange="-24 24"/>
          <geom type="mesh" contype="0" conaffinity="0" group="1" density="0" mesh="thigh1"/>
          <geom size="0.02 0.0225 0.1" pos="-0.015 0 -0.08" type="box"/>
          <body name="HR_SHANK" pos="0 0 -0.2">
            <inertial pos="0.0064794 -1.4529e-06 -0.12157" quat="0.707107 0 0 0.707107" mass="0.153" diaginertia="0.00090672 0.00089039 3.1266e-05"/>
            <joint name="HR_Knee_joint" pos="0 0 0" axis="0 -1 0" range="0.524 2.792" actuatorfrcrange="-36 36"/>
            <geom type="mesh" contype="0" conaffinity="0" group="1" density="0" mesh="shank"/>
            <geom size="0.015 0.06" pos="0.005 0 -0.03" quat="0.995004 0 -0.0998334 0" type="cylinder"/>
            <geom size="0.015 0.05" pos="0.01 0 -0.14" quat="0.997189 0 0.0749297 0" type="cylinder"/>
            <body name="HR_FOOT" pos="0 0 -0.21012">
              <inertial pos="0 0 0" mass="0.02" diaginertia="0 0 0"/>
              <geom size="0.022" quat="0.707107 0.707107 0 0"/>
            </body>
          </body>
        </body>
      </body>
    </body>
  </worldbody>
</mujoco>
